Workbook

Sheet FBCJ Jul-Des 2025
A1: PT SMART Tbk. (Downstream | E1: CASH JOURNAL
A2: Jakarta | E2: R124:KAS BESAR | H2: Rupiah
A3: 3300 | E3: 3301 | F3: 10000001
A4: 01.07.2025 | C4: - | D4: 31.12.2025
J6: 45000000 | M6: IDR
B8: Pstng Date | E8: Reference | F8: Business Trans. | H8: Expenses | I8: Receipt recipient | K8: Rev.Doc.No
B9: G/L acct | C9: G/L acct | D9: Cost Ctr | G9: Text for item | N9: G/L acct | O9: Cost Ctr
B10: 07.07.2025 | C10: 70107300 | D10: R124D1HRDV | E10: 510/PPC/VI/2025 | F10: OLAHRAGA DAN PERMAINAN | G10: BY OLAHRAGA 20/06/2025 | H10: 400000 | I10: DEWI PRIYANTI | N10: =+C10 -> 70107300 | O10: =+D10 -> R124D1HRDV
B11: 07.07.2025 | C11: 70009110 | D11: P206D1SLSS | E11: 498/PPC/VI/2025 | F11: SURVEY DAN ANALISA | G11: BY COO KADIN ASSUDAMAL EBP 2411775352 | H11: 100000 | I11: ORIENTASI | N11: =+C11 -> 70009110 | O11: =+D11 -> P206D1SLSS
B12: 07.07.2025 | C12: 70009110 | D12: P206D1SLSS | E12: 498/PPC/VI/2025 | F12: SURVEY DAN ANALISA | G12: BY COO KADIN ASSUDAMAL EBP 2411775353 | H12: 100000 | I12: ORIENTASI | N12: =+C12 -> 70009110 | O12: =+D12 -> P206D1SLSS
B13: 07.07.2025 | C13: 70009110 | D13: P206D1SLSS | E13: 498/PPC/VI/2025 | F13: SURVEY DAN ANALISA | G13: BY COO KADIN ASSUDAMAL EBP 2411775354 | H13: 150000 | I13: ORIENTASI | N13: =+C13 -> 70009110 | O13: =+D13 -> P206D1SLSS
B14: 07.07.2025 | C14: 70009110 | D14: C206D1SLSS | E14: 498/PPC/VI/2025 | F14: SURVEY DAN ANALISA | G14: BY COO KADIN ASSUDAMAL EBP 2411775666 | H14: 100000 | I14: ORIENTASI | N14: =+C14 -> 70009110 | O14: =+D14 -> C206D1SLSS
B15: 07.07.2025 | C15: 70009110 | D15: P206D1SLSS | E15: 498/PPC/VI/2025 | F15: SURVEY DAN ANALISA | G15: BY COO KADIN ASSUDAMAL EBP 2411775667 | H15: 100000 | I15: ORIENTASI | N15: =+C15 -> 70009110 | O15: =+D15 -> P206D1SLSS
B16: 07.07.2025 | C16: 70009110 | D16: P206D1SLSS | E16: 498/PPC/VI/2025 | F16: SURVEY DAN ANALISA | G16: BY COO KADIN ASSUDAMAL EBP 2411775668 | H16: 100000 | I16: ORIENTASI | N16: =+C16 -> 70009110 | O16: =+D16 -> P206D1SLSS
B17: 07.07.2025 | C17: 70009110 | D17: C206D1SLSS | E17: 498/PPC/VI/2025 | F17: SURVEY DAN ANALISA | G17: BY COO KADIN ASSUDAMAL EBP 2411775669 | H17: 100000 | I17: ORIENTASI | N17: =+C17 -> 70009110 | O17: =+D17 -> C206D1SLSS
B18: 07.07.2025 | C18: 70009110 | D18: P206D1SLSS | E18: 498/PPC/VI/2025 | F18: SURVEY DAN ANALISA | G18: BY COO KADIN ASSUDAMAL EBP 2411775670 | H18: 100000 | I18: ORIENTASI | N18: =+C18 -> 70009110 | O18: =+D18 -> P206D1SLSS
B19: 07.07.2025 | C19: 70009110 | D19: P206D1SLSS | E19: 498/PPC/VI/2025 | F19: SURVEY DAN ANALISA | G19: BY COO KADIN ASSUDAMAL EBP 2411775671 | H19: 100000 | I19: ORIENTASI | N19: =+C19 -> 70009110 | O19: =+D19 -> P206D1SLSS
B20: 07.07.2025 | C20: 70009110 | D20: P206D1SLSS | E20: 498/PPC/VI/2025 | F20: SURVEY DAN ANALISA | G20: BY HC BPOM AL JAZIRA EBP 2411775754 | H20: 50000 | I20: ORIENTASI | N20: =+C20 -> 70009110 | O20: =+D20 -> P206D1SLSS
B21: 07.07.2025 | C21: 70101202 | D21: R124NSS | E21: 504/PPC/VI/2025 | F21: PEMEL.KEND&A.BERAT MATRL | G21: BY PEMBELIAN CAIRAN PENETRANT DAN CLEANER | H21: 940000 | I21: HADI SUPENO | N21: =+C21 -> 70101202 | O21: =+D21 -> R124NSS
... B148: 11.07.2025 | C148: 70009110 | D148: P206D1SLSS | E148: 558/PPC/VII/2025 | F148: SURVEY DAN ANALISA | G148: BY HC HOME CHAIN EBP 2411775613 | H148: 50000 | I148: SANTI | N148: =+C148 -> 70009110 | O148: =+D148 -> P206D1SLSS
B149: 11.07.2025 | C149: 16.07.2025 | D149: R124TCP | F149: BANK IN TRANSIT | H149: 0 | I149: PT. SMART Tbk | N149: =+C149 -> 16.07.2025 | O149: =+D149 -> R124TCP
B150: 16.07.2025 | C150: 70101114 | D150: R124TCP | F150: PBAIKN&PRAWATN PRABT MATR | G150: BY PEMB EXHAUST FAN, TIMP FLOOR MARKING | H150: 629000 | I150: ARDHIAN Y | N150: =+C150 -> 70101114 | O150: =+D150 -> R124TCP
B151: 16.07.2025 | C151: 70101202 | D151: R124REF3 | F151: PEMEL.KEND&A.BERAT MATRL | G151: BY PEMB WIPER SPRING U/ MOTOR POMPA F204 | H151: 303100 | I151: M. NUR HUDA | N151: =+C151 -> 70101202 | O151: =+D151 -> R124REF3
B152: 16.07.2025 | C152: 70107100 | D152: R124D1HRGA | F152: BIAYA MESS | G152: BY PDAM MESS PKTJAND JULI 2025 | H152: 290500 | I152: IFAN SAFRIANTO | N152: =+C152 -> 70107100 | O152: =+D152 -> R124D1HRGA
B153: 16.07.2025 | C153: 70108110 | D153: R124QMR | F153: PERLENGKAPAN FOTOCOPY | G153: BY CETAK POSTER, BANNER, TAGGING PRP | H153: 304800 | I153: LILA | N153: =+C153 -> 70108110 | O153: =+D153 -> R124QMR
B154: 16.07.2025 | C154: 70107300 | D154: R124D1HRDV | F154: OLAHRAGA DAN PERMAINAN | G154: BY OLAHRAGA 11/07/2025 | H154: 500000 | I154: DEWI PRIYANTI | N154: =+C154 -> 70107300 | O154: =+D154 -> R124D1HRDV
B155: 16.07.2025 | C155: 70107600 | D155: R124D1HRGA | F155: MAKANAN DAN MINUMAN | G155: BY SNACK KUNJUNGAN SLF | H155: 331500 | I155: IFAN SAFRIANTO | N155: =+C155 -> 70107600 | O155: =+D155 -> R124D1HRGA
B156: 16.07.2025 | C156: 70119300 | D156: R124D1PRCN | F156: UMUM & ADMIN LAIN | G156: BY PEMB MATERAI | H156: 1000000 | I156: ANTONIUS L | N156: =+C156 -> 70119300 | O156: =+D156 -> R124D1PRCN
B157: 16.07.2025 | C157: 70101102 | D157: R124REF | F157: PEMEL.BNGAN&PSARANA MATRL | G157: BY PEMB KUAS U/ CAT | H157: 153000 | I157: TRI SUMARNO | N157: =+C157 -> 70101102 | O157: =+D157 -> R124REF
B158: 16.07.2025 | C158: 70009110 | D158: P206D1SLSS | F158: SURVEY DAN ANALISA | G158: BY HC SG OILSEED EBP 2411776092 | H158: 50000 | I158: FELISIA | N158: =+C158 -> 70009110 | O158: =+D158 -> P206D1SLSS
B159: 16.07.2025 | C159: 70009110 | D159: P206D1SLSS | F159: SURVEY DAN ANALISA | G159: BY HC SG OILSEED EBP 2411776096 | H159: 50000 | I159: FELISIA | N159: =+C159 -> 70009110 | O159: =+D159 -> P206D1SLSS
B160: 16.07.2025 | C160: 70009110 | D160: P206D1SLSS | F160: SURVEY DAN ANALISA | G160: BY HC MONDELEZ EBP 2411776205 | H160: 50000 | I160: FELISIA | N160: =+C160 -> 70009110 | O160: =+D160 -> P206D1SLSS
B161: 16.07.2025 | C161: 70009110 | D161: P206D1SLSS | F161: SURVEY DAN ANALISA | G161: BY HC THAI GLICO EBP 2411776134 | H161: 50000 | I161: CHRISTIE ADRIAN | N161: =+C161 -> 70009110 | O161: =+D161 -> P206D1SLSS
... B178: 17.07.2025 | C178: 70107600 | D178: R124D1MGMT | F178: MAKANAN DAN MINUMAN | G178: BY KONSUMSI SC MEETING 17/07/2025 | H178: 500000 | I178: DEWI PRIYANTI | N178: =+C178 -> 70107600 | O178: =+D178 -> R124D1MGMT
B179: 25.07.2025 | C179: 70101202 | D179: R124WTT | E179: 571/PPC/VII/2025 | F179: PEMEL.KEND&A.BERAT MATRL | G179: BY PEMB NIPPLE SELANG PVC, ELBOW SS, DLL | H179: 991000 | I179: SUGIANTORO | N179: =+C179 -> 70101202 | O179: =+D179 -> R124WTT
B180: 25.07.2025 | C180: 70101114 | D180: R124NSS | E180: 577/PPC/VII/2025 | F180: PBAIKN&PRAWATN PRABT MATR | G180: BY PEMB TANGGA LIPAT TELESKOPIK | H180: 904127 | I180: HADI SUPENO | N180: =+C180 -> 70101114 | O180: =+D180 -> R124NSS
B181: 25.07.2025 | C181: 70009110 | D181: P206D1SLSS | E181: 587/PPC/VII/2025 | F181: SURVEY DAN ANALISA | G181: BY HC AST PVT EBP 2411776266 | H181: 50000 | I181: RIZKY R | N181: =+C181 -> 70009110 | O181: =+D181 -> P206D1SLSS
B182: 25.07.2025 | C182: 70009110 | D182: P206D1SLSS | E182: 587/PPC/VII/2025 | F182: SURVEY DAN ANALISA | G182: BY HC SG OILSEED EBP 2411775747 | H182: 50000 | I182: RIZKY R | N182: =+C182 -> 70009110 | O182: =+D182 -> P206D1SLSS
B183: 25.07.2025 | C183: 70009110 | D183: P206D1SLSS | E183: 587/PPC/VII/2025 | F183: SURVEY DAN ANALISA | G183: BY HC SG OILSEED EBP 2411776233 | H183: 50000 | I183: RIZKY R | N183: =+C183 -> 70009110 | O183: =+D183 -> P206D1SLSS
B184: 25.07.2025 | C184: 70009110 | D184: P206D1SLSS | E184: 587/PPC/VII/2025 | F184: SURVEY DAN ANALISA | G184: BY COO KADIN AST PVT EBP 2411776266 | H184: 200000 | I184: RIZKY R | N184: =+C184 -> 70009110 | O184: =+D184 -> P206D1SLSS
...

Sheet FBL3N
A2: G/L Account | E2: 10000001 | G2: Kas Kecil Unit 01
A3: Company Code | E3: 3300
C6: Account | D6: Doc. Date | F6: DocumentNo | H6: Pstng Date | I6: PK | J6: Amount in doc. curr. | K6: Curr. | L6: Amount in local cur. | M6: LCurr | N6: Quantity | O6: BUn | P6: Cost Ctr | Q6: Profit Ctr | R6: Reference | S6: Document Header Text | T6: Text | U6: Tr.Prt | V6: Ref.key (header) 1 | W6: Ref.key (header) 2 | X6: Type | Y6: Clrng doc. | Z6: Assignment
C8: 10000001 | D8: 31.12.2025 | F8: 1888429 | H8: 31.12.2025 | I8: 50 | J8: 0 | K8: IDR | L8: 0 | M8: IDR | Q8: R124 | S8: FC Valuation | T8: 10000001 - Valuation on 20251231 | X8: SA | Y8: 1003022 | Z8: 20251231
C9: 10000001 | D9: 30.06.2025 | F9: 1413583 | H9: 01.07.2025 | I9: 40 | J9: 0 | K9: IDR | L9: 0 | M9: IDR | Q9: R124 | S9: Reverse posting | T9: 10000001 - Valuation on 20250630 Reversal | X9: SA | Y9: 1415341 | Z9: 20250701
C10: 10000001 | D10: 03.07.2025 | F10: 1415341 | H10: 03.07.2025 | I10: 40 | J10: 0 | K10: IDR | L10: 0 | M10: IDR | Q10: R124 | S10: Autom.clearing SAPF124 | T10: 10000001 - Valuation on 20250630 | X10: AB | Y10: 1415341 | Z10: 20250703
C11: 10000001 | D11: 03.07.2025 | F11: 1415341 | H11: 03.07.2025 | I11: 50 | J11: 0 | K11: IDR | L11: 0 | M11: IDR | Q11: R124 | S11: Autom.clearing SAPF124 | T11: 10000001 - Valuation on 20250630 Reversal | X11: AB | Y11: 1415341 | Z11: 20250703
C12: 10000001 | D12: 07.07.2025 | F12: 12005321 | H12: 07.07.2025 | I12: 50 | J12: -400000 | K12: IDR | L12: -400000 | M12: IDR | Q12: R124 | R12: 510/PPC/VI/2025 | S12: OLAHRAGA DAN PERMAINAN | T12: BY OLAHRAGA 20/06/2025 | X12: SP | Y12: 1495275 | Z12: 20250707
C13: 10000001 | D13: 07.07.2025 | F13: 12005322 | H13: 07.07.2025 | I13: 50 | J13: -100000 | K13: IDR | L13: -100000 | M13: IDR | Q13: R124 | R13: 498/PPC/VI/2025 | S13: SURVEY DAN ANALISA | T13: BY COO KADIN ASSUDAMAL EBP 2411775352 | X13: SP | Y13: 1495275 | Z13: 20250707
C14: 10000001 | D14: 07.07.2025 | F14: 12005323 | H14: 07.07.2025 | I14: 50 | J14: -100000 | K14: IDR | L14: -100000 | M14: IDR | Q14: R124 | R14: 498/PPC/VI/2025 | S14: SURVEY DAN ANALISA | T14: BY COO KADIN ASSUDAMAL EBP 2411775353 | X14: SP | Y14: 1495275 | Z14: 20250707
C15: 10000001 | D15: 07.07.2025 | F15: 12005324 | H15: 07.07.2025 | I15: 50 | J15: -150000 | K15: IDR | L15: -150000 | M15: IDR | Q15: R124 | R15: 498/PPC/VI/2025 | S15: SURVEY DAN ANALISA | T15: BY COO KADIN ASSUDAMAL EBP 2411775354 | X15: SP | Y15: 1495275 | Z15: 20250707
C16: 10000001 | D16: 07.07.2025 | F16: 12005325 | H16: 07.07.2025 | I16: 50 | J16: -100000 | K16: IDR | L16: -100000 | M16: IDR | Q16: R124 | R16: 498/PPC/VI/2025 | S16: SURVEY DAN ANALISA | T16: BY COO KADIN ASSUDAMAL EBP 2411775666 | X16: SP | Y16: 1495275 | Z16: 20250707
C17: 10000001 | D17: 07.07.2025 | F17: 12005326 | H17: 07.07.2025 | I17: 50 | J17: -100000 | K17: IDR | L17: -100000 | M17: IDR | Q17: R124 | R17: 498/PPC/VI/2025 | S17: SURVEY DAN ANALISA | T17: BY COO KADIN ASSUDAMAL EBP 2411775667 | X17: SP | Y17: 1495275 | Z17: 20250707
C18: 10000001 | D18: 07.07.2025 | F18: 12005327 | H18: 07.07.2025 | I18: 50 | J18: -100000 | K18: IDR | L18: -100000 | M18: IDR | Q18: R124 | R18: 498/PPC/VI/2025 | S18: SURVEY DAN ANALISA | T18: BY COO KADIN ASSUDAMAL EBP 2411775668 | X18: SP | Y18: 1495275 | Z18: 20250707
C19: 10000001 | D19: 07.07.2025 | F19: 12005328 | H19: 07.07.2025 | I19: 50 | J19: -100000 | K19: IDR | L19: -100000 | M19: IDR | Q19: R124 | R19: 498/PPC/VI/2025 | S19: SURVEY DAN ANALISA | T19: BY COO KADIN ASSUDAMAL EBP 2411775669 | X19: SP | Y19: 1495275 | Z19: 20250707
C20: 10000001 | D20: 07.07.2025 | F20: 12005329 | H20: 07.07.2025 | I20: 50 | J20: -100000 | K20: IDR | L20: -100000 | M20: IDR | Q20: R124 | R20: 498/PPC/VI/2025 | S20: SURVEY DAN ANALISA | T20: BY COO KADIN ASSUDAMAL EBP 2411775670 | X20: SP | Y20: 1495275 | Z20: 20250707
C21: 10000001 | D21: 07.07.2025 | F21: 12005330 | H21: 07.07.2025 | I21: 50 | J21: -100000 | K21: IDR | L21: -100000 | M21: IDR | Q21: R124 | R21: 498/PPC/VI/2025 | S21: SURVEY DAN ANALISA | T21: BY COO KADIN ASSUDAMAL EBP 2411775671 | X21: SP | Y21: 1495275 | Z21: 20250707
C22: 10000001 | D22: 07.07.2025 | F22: 12005331 | H22: 07.07.2025 | I22: 50 | J22: -50000 | K22: IDR | L22: -50000 | M22: IDR | Q22: R124 | R22: 498/PPC/VI/2025 | S22: SURVEY DAN ANALISA | T22: BY HC BPOM AL JAZIRA EBP 2411775754 | X22: SP | Y22: 1495275 | Z22: 20250707
C23: 10000001 | D23: 07.07.2025 | F23: 12005332 | H23: 07.07.2025 | I23: 50 | J23: -940000 | K23: IDR | L23: -940000 | M23: IDR | Q23: R124 | R23: 504/PPC/VI/2025 | S23: PEMEL.KEND&A.BERAT MATRL | T23: BY PEMBELIAN CAIRAN PENETRANT DAN CLEANER | X23: SP | Y23: 1495275 | Z23: 20250707
... C150: 10000001 | D150: 11.07.2025 | F150: 12005459 | H150: 11.07.2025 | I150: 50 | J150: -50000 | K150: IDR | L150: -50000 | M150: IDR | Q150: R124 | R150: 558/PPC/VII/2025 | S150: SURVEY DAN ANALISA | T150: BY HC HOME CHAIN EBP 2411775613 | X150: SP | Y150: 1495275 | Z150: 20250711
C151: 10000001 | D151: 11.07.2025 | F151: 12005460 | H151: 11.07.2025 | I151: 40 | J151: 32056775 | K151: IDR | L151: 32056775 | M151: IDR | Q151: R124 | S151: BANK IN TRANSIT | T151: PETTY CASH RUNGKUT SURABAYA PERIODE 01-11 JULI 25 | X151: SP | Y151: 1495275 | Z151: 20250711
C152: 10000001 | D152: 16.07.2025 | F152: 12005952 | H152: 16.07.2025 | I152: 50 | J152: -629000 | K152: IDR | L152: -629000 | M152: IDR | Q152: R124 | S152: PBAIKN&PRAWATN PRABT MATR | T152: BY PEMB EXHAUST FAN, TIMP FLOOR MARKING | X152: SP | Y152: 1495275 | Z152: 20250716
C153: 10000001 | D153: 16.07.2025 | F153: 12005953 | H153: 16.07.2025 | I153: 50 | J153: -303100 | K153: IDR | L153: -303100 | M153: IDR | Q153: R124 | S153: PEMEL.KEND&A.BERAT MATRL | T153: BY PEMB WIPER SPRING U/ MOTOR POMPA F204 | X153: SP | Y153: 1495275 | Z153: 20250716
C154: 10000001 | D154: 16.07.2025 | F154: 12005954 | H154: 16.07.2025 | I154: 50 | J154: -290500 | K154: IDR | L154: -290500 | M154: IDR | Q154: R124 | S154: BIAYA MESS | T154: BY PDAM MESS PKTJAND JULI 2025 | X154: SP | Y154: 1495275 | Z154: 20250716
C155: 10000001 | D155: 16.07.2025 | F155: 12005955 | H155: 16.07.2025 | I155: 50 | J155: -304800 | K155: IDR | L155: -304800 | M155: IDR | Q155: R124 | S155: PERLENGKAPAN FOTOCOPY | T155: BY CETAK POSTER, BANNER, TAGGING PRP | X155: SP | Y155: 1495275 | Z155: 20250716
C156: 10000001 | D156: 16.07.2025 | F156: 12005956 | H156: 16.07.2025 | I156: 50 | J156: -500000 | K156: IDR | L156: -500000 | M156: IDR | Q156: R124 | S156: OLAHRAGA DAN PERMAINAN | T156: BY OLAHRAGA 11/07/2025 | X156: SP | Y156: 1495275 | Z156: 20250716
C157: 10000001 | D157: 16.07.2025 | F157: 12005957 | H157: 16.07.2025 | I157: 50 | J157: -331500 | K157: IDR | L157: -331500 | M157: IDR | Q157: R124 | S157: MAKANAN DAN MINUMAN | T157: BY SNACK KUNJUNGAN SLF | X157: SP | Y157: 1495275 | Z157: 20250716
C158: 10000001 | D158: 16.07.2025 | F158: 12005958 | H158: 16.07.2025 | I158: 50 | J158: -1000000 | K158: IDR | L158: -1000000 | M158: IDR | Q158: R124 | S158: UMUM & ADMIN LAIN | T158: BY PEMB MATERAI | X158: SP | Y158: 1495275 | Z158: 20250716
C159: 10000001 | D159: 16.07.2025 | F159: 12005959 | H159: 16.07.2025 | I159: 50 | J159: -153000 | K159: IDR | L159: -153000 | M159: IDR | Q159: R124 | S159: PEMEL.BNGAN&PSARANA MATRL | T159: BY PEMB KUAS U/ CAT | X159: SP | Y159: 1495275 | Z159: 20250716
C160: 10000001 | D160: 16.07.2025 | F160: 12005960 | H160: 16.07.2025 | I160: 50 | J160: -50000 | K160: IDR | L160: -50000 | M160: IDR | Q160: R124 | S160: SURVEY DAN ANALISA | T160: BY HC SG OILSEED EBP 2411776092 | X160: SP | Y160: 1495275 | Z160: 20250716
C161: 10000001 | D161: 16.07.2025 | F161: 12005961 | H161: 16.07.2025 | I161: 50 | J161: -50000 | K161: IDR | L161: -50000 | M161: IDR | Q161: R124 | S161: SURVEY DAN ANALISA | T161: BY HC SG OILSEED EBP 2411776096 | X161: SP | Y161: 1495275 | Z161: 20250716
C162: 10000001 | D162: 16.07.2025 | F162: 12005962 | H162: 16.07.2025 | I162: 50 | J162: -50000 | K162: IDR | L162: -50000 | M162: IDR | Q162: R124 | S162: SURVEY DAN ANALISA | T162: BY HC MONDELEZ EBP 2411776205 | X162: SP | Y162: 1495275 | Z162: 20250716
... C180: 10000001 | D180: 17.07.2025 | F180: 12005980 | H180: 17.07.2025 | I180: 50 | J180: -500000 | K180: IDR | L180: -500000 | M180: IDR | Q180: R124 | S180: MAKANAN DAN MINUMAN | T180: BY KONSUMSI SC MEETING 17/07/2025 | X180: SP | Y180: 1495275 | Z180: 20250717
C181: 10000001 | D181: 25.07.2025 | F181: 12005981 | H181: 25.07.2025 | I181: 50 | J181: -991000 | K181: IDR | L181: -991000 | M181: IDR | Q181: R124 | R181: 571/PPC/VII/2025 | S181: PEMEL.KEND&A.BERAT MATRL | T181: BY PEMB NIPPLE SELANG PVC, ELBOW SS, DLL | X181: SP | Y181: 1495275 | Z181: 20250725
C182: 10000001 | D182: 25.07.2025 | F182: 12005982 | H182: 25.07.2025 | I182: 50 | J182: -904127 | K182: IDR | L182: -904127 | M182: IDR | Q182: R124 | R182: 577/PPC/VII/2025 | S182: PBAIKN&PRAWATN PRABT MATR | T182: BY PEMB TANGGA LIPAT TELESKOPIK | X182: SP | Y182: 1495275 | Z182: 20250725
C183: 10000001 | D183: 25.07.2025 | F183: 12005983 | H183: 25.07.2025 | I183: 50 | J183: -50000 | K183: IDR | L183: -50000 | M183: IDR | Q183: R124 | R183: 587/PPC/VII/2025 | S183: SURVEY DAN ANALISA | T183: BY HC AST PVT EBP 2411776266 | X183: SP | Y183: 1495275 | Z183: 20250725
C184: 10000001 | D184: 25.07.2025 | F184: 12005984 | H184: 25.07.2025 | I184: 50 | J184: -50000 | K184: IDR | L184: -50000 | M184: IDR | Q184: R124 | R184: 587/PPC/VII/2025 | S184: SURVEY DAN ANALISA | T184: BY HC SG OILSEED EBP 2411775747 | X184: SP | Y184: 1495275 | Z184: 20250725
C185: 10000001 | D185: 25.07.2025 | F185: 12005985 | H185: 25.07.2025 | I185: 50 | J185: -50000 | K185: IDR | L185: -50000 | M185: IDR | Q185: R124 | R185: 587/PPC/VII/2025 | S185: SURVEY DAN ANALISA | T185: BY HC SG OILSEED EBP 2411776233 | X185: SP | Y185: 1495275 | Z185: 20250725
C186: 10000001 | D186: 25.07.2025 | F186: 12005986 | H186: 25.07.2025 | I186: 50 | J186: -200000 | K186: IDR | L186: -200000 | M186: IDR | Q186: R124 | R186: 587/PPC/VII/2025 | S186: SURVEY DAN ANALISA | T186: BY COO KADIN AST PVT EBP 2411776266 | X186: SP | Y186: 1495275 | Z186: 20250725
C187: 10000001 | D187: 25.07.2025 | F187: 12005987 | H187: 25.07.2025 | I187: 50 | J187: -301000 | K187: IDR | L187: -301000 | M187: IDR | Q187: R124 | R187: 592/PPC/VII/2025 | S187: RISET/PENGEMBANGAN PRODUK | T187: BY SENSORY KFC, McD | X187: SP | Y187: 1495275 | Z187: 20250725
...

Sheet Sheet2
A3: Sum of Amount in doc. curr. | B3: Column Labels
A4: Row Labels | B4: 07 | C4: 08 | D4: 09 | E4: 10 | F4: 11 | G4: 12 | H4: (blank) | I4: Grand Total
A5: - | B5: -131000 | C5: -930000 | D5: -1203853 | E5: -1469656 | F5: -4791052 | G5: -3214369 | I5: -11739930
A6: 15000900 | B6: -131000 | C6: -930000 | D6: -1203853 | E6: -1469656 | F6: -4791052 | G6: -3214369 | I6: -11739930
A7: C206D1SLSS | B7: -820000 | C7: -1870000 | D7: -1280000 | E7: -2775000 | F7: -1778000 | G7: -1630000 | I7: -10153000
A8: 70001110 | F8: -1420000 | G8: -1300000 | I8: -2720000
A9: 70009110 | B9: -400000 | C9: -1350000 | D9: -850000 | E9: -2400000 | I9: -5000000
A10: 70101202 | B10: -420000 | C10: -520000 | D10: -430000 | E10: -375000 | F10: -358000 | G10: -330000 | I10: -2433000
A11: H200D1MMDP | E11: -135000 | F11: -7478800 | G11: -1335000 | I11: -8948800
A12: 70110210 | E12: -135000 | F12: -7478800 | G12: -1335000 | I12: -8948800
A13: M204D1COMM | B13: -3702000 | C13: -4927000 | D13: -763000 | E13: -3540000 | F13: -1120000 | G13: -1730300 | I13: -15782300
A14: 70001110 | B14: -29000 | C14: -18000 | D14: -13000 | E14: -24000 | F14: -1120000 | G14: -1218000 | I14: -2422000
A15: 70009110 | B15: -1150000 | C15: -700000 | D15: -750000 | E15: -2600000 | I15: -5200000
A16: 70105321 | E16: -916000 | I16: -916000
A17: 70107600 | B17: -945000 | I17: -945000
A18: 70115100 | B18: -1578000 | C18: -4209000 | G18: -512300 | I18: -6299300
A19: P206D1SLSC | B19: -350000 | C19: -350000 | D19: -700000 | E19: -400000 | F19: -400000 | G19: -500000 | I19: -2700000
A20: 70001110 | F20: -400000 | G20: -500000 | I20: -900000
A21: 70009110 | B21: -350000 | C21: -350000 | D21: -700000 | E21: -400000 | I21: -1800000
A22: P206D1SLSS | B22: -6844000 | C22: -4844100 | D22: -3643000 | E22: -5837000 | F22: -6200000 | G22: -5701000 | I22: -33069100
A23: 70001110 | C23: -868100 | F23: -4250000 | G23: -3900000 | I23: -9018100
A24: 70009110 | B24: -5100000 | C24: -3200000 | D24: -2900000 | E24: -3950000 | I24: -15150000
A25: 70101202 | B25: -328000 | C25: -321000 | D25: -298000 | E25: -300000 | F25: -452000 | G25: -310000 | I25: -2009000
A26: 70106100 | B26: -394000 | C26: -382000 | D26: -445000 | E26: -422000 | F26: -432000 | G26: -437000 | I26: -2512000
A27: 70108110 | B27: -22000 | C27: -23000 | E27: -15000 | F27: -16000 | G27: -28000 | I27: -104000
A28: 70119300 | B28: -1000000 | C28: -50000 | E28: -1150000 | F28: -1050000 | G28: -1026000 | I28: -4276000
A29: R124BLR | E29: -2325000 | F29: -2821000 | I29: -5146000
A30: 70101114 | E30: -331000 | I30: -331000
A31: 70101202 | F31: -200000 | I31: -200000
A32: 70106100 | E32: -931500 | F32: -2121000 | I32: -3052500
A33: 70107600 | E33: -1062500 | F33: -500000 | I33: -1562500
A34: R124D1EHFS | B34: -1273180 | C34: -1113500 | D34: -100000 | E34: -999700 | F34: -876800 | G34: -996262 | I34: -5359442
A35: 70101114 | F35: -50000 | I35: -50000
A36: 70102300 | B36: -1116900 | I36: -1116900
A37: 70107600 | B37: -156280 | C37: -766500 | D37: -100000 | E37: -999700 | F37: -826800 | G37: -996262 | I37: -3845542
A38: 70108110 | C38: -347000 | I38: -347000
A39: R124D1FRCO | B39: -383350 | C39: -344000 | E39: -511000 | F39: -543200 | G39: -865000 | I39: -2646550
A40: 70101202 | C40: -269000 | E40: -361000 | G40: -637500 | I40: -1267500
A41: 70107600 | C41: -75000 | E41: -150000 | G41: -76000 | I41: -301000
A42: 70108100 | B42: -383350 | F42: -543200 | G42: -151500 | I42: -1078050
...

Sheet List Petty Cash Jul-Des 25
A2: G/L Account | E2: 10000001 | G2: Kas Kecil Unit 01
A3: Company Code | E3: 3300
C6: Account | D6: Doc. Date | F6: DocumentNo | H6: Pstng Date | I6: Month | J6: PK | K6: Amount in doc. curr. | L6: Curr. | M6: Amount in local cur. | N6: LCurr | O6: Quantity | P6: BUn | Q6: Cost Ctr | R6: Profit Ctr | S6: Reference | T6: Document Header Text | U6: Text | V6: GL Account | W6: Nama GL Account | X6: Cost Center | Y6: Type | Z6: Clrng doc. | AA6: Assignment | AB6: Amount in doc. curr.
C7: 10000001 | D7: 07.07.2025 | F7: 12005321 | H7: 07.07.2025 | I7: =+MID(H7,4,2) -> 07 | J7: 50 | K7: -400000 | L7: IDR | M7: -400000 | N7: IDR | R7: R124 | S7: 510/PPC/VI/2025 | T7: OLAHRAGA DAN PERMAINAN | U7: BY OLAHRAGA 20/06/2025 | V7: =+VLOOKUP(U7,'FBCJ Jul-Des 2025'!$G$10:$P$1302,8,0) -> 70107300 | W7: =+VLOOKUP(V7,Sheet1!$A$2:$B$27,2,0) -> Biaya Olahraga Dan Permainan | X7: =+VLOOKUP(U7,'FBCJ Jul-Des 2025'!$G$10:$P$1302,9,0) -> R124D1HRDV | Y7: SP | Z7: 1495275 | AA7: 20250707 | AB7: 400000
C8: 10000001 | D8: 07.07.2025 | F8: 12005322 | H8: 07.07.2025 | I8: =+MID(H8,4,2) -> 07 | J8: 50 | K8: -100000 | L8: IDR | M8: -100000 | N8: IDR | R8: R124 | S8: 498/PPC/VI/2025 | T8: SURVEY DAN ANALISA | U8: BY COO KADIN ASSUDAMAL EBP 2411775352 | V8: =+VLOOKUP(U8,'FBCJ Jul-Des 2025'!$G$10:$P$1302,8,0) -> 70009110 | W8: =+VLOOKUP(V8,Sheet1!$A$2:$B$27,2,0) -> Biaya Survey dan Analisa | X8: =+VLOOKUP(U8,'FBCJ Jul-Des 2025'!$G$10:$P$1302,9,0) -> P206D1SLSS | Y8: SP | Z8: 1495275 | AA8: 20250707 | AB8: 100000
C9: 10000001 | D9: 07.07.2025 | F9: 12005323 | H9: 07.07.2025 | I9: =+MID(H9,4,2) -> 07 | J9: 50 | K9: -100000 | L9: IDR | M9: -100000 | N9: IDR | R9: R124 | S9: 498/PPC/VI/2025 | T9: SURVEY DAN ANALISA | U9: BY COO KADIN ASSUDAMAL EBP 2411775353 | V9: =+VLOOKUP(U9,'FBCJ Jul-Des 2025'!$G$10:$P$1302,8,0) -> 70009110 | W9: =+VLOOKUP(V9,Sheet1!$A$2:$B$27,2,0) -> Biaya Survey dan Analisa | X9: =+VLOOKUP(U9,'FBCJ Jul-Des 2025'!$G$10:$P$1302,9,0) -> P206D1SLSS | Y9: SP | Z9: 1495275 | AA9: 20250707 | AB9: 100000
C10: 10000001 | D10: 07.07.2025 | F10: 12005324 | H10: 07.07.2025 | I10: =+MID(H10,4,2) -> 07 | J10: 50 | K10: -150000 | L10: IDR | M10: -150000 | N10: IDR | R10: R124 | S10: 498/PPC/VI/2025 | T10: SURVEY DAN ANALISA | U10: BY COO KADIN ASSUDAMAL EBP 2411775354 | V10: =+VLOOKUP(U10,'FBCJ Jul-Des 2025'!$G$10:$P$1302,8,0) -> 70009110 | W10: =+VLOOKUP(V10,Sheet1!$A$2:$B$27,2,0) -> Biaya Survey dan Analisa | X10: =+VLOOKUP(U10,'FBCJ Jul-Des 2025'!$G$10:$P$1302,9,0) -> P206D1SLSS | Y10: SP | Z10: 1495275 | AA10: 20250707 | AB10: 150000
C11: 10000001 | D11: 07.07.2025 | F11: 12005325 | H11: 07.07.2025 | I11: =+MID(H11,4,2) -> 07 | J11: 50 | K11: -100000 | L11: IDR | M11: -100000 | N11: IDR | R11: R124 | S11: 498/PPC/VI/2025 | T11: SURVEY DAN ANALISA | U11: BY COO KADIN ASSUDAMAL EBP 2411775666 | V11: =+VLOOKUP(U11,'FBCJ Jul-Des 2025'!$G$10:$P$1302,8,0) -> 70009110 | W11: =+VLOOKUP(V11,Sheet1!$A$2:$B$27,2,0) -> Biaya Survey dan Analisa | X11: =+VLOOKUP(U11,'FBCJ Jul-Des 2025'!$G$10:$P$1302,9,0) -> C206D1SLSS | Y11: SP | Z11: 1495275 | AA11: 20250707 | AB11: 100000
C12: 10000001 | D12: 07.07.2025 | F12: 12005326 | H12: 07.07.2025 | I12: =+MID(H12,4,2) -> 07 | J12: 50 | K12: -100000 | L12: IDR | M12: -100000 | N12: IDR | R12: R124 | S12: 498/PPC/VI/2025 | T12: SURVEY DAN ANALISA | U12: BY COO KADIN ASSUDAMAL EBP 2411775667 | V12: =+VLOOKUP(U12,'FBCJ Jul-Des 2025'!$G$10:$P$1302,8,0) -> 70009110 | W12: =+VLOOKUP(V12,Sheet1!$A$2:$B$27,2,0) -> Biaya Survey dan Analisa | X12: =+VLOOKUP(U12,'FBCJ Jul-Des 2025'!$G$10:$P$1302,9,0) -> P206D1SLSS | Y12: SP | Z12: 1495275 | AA12: 20250707 | AB12: 100000
C13: 10000001 | D13: 07.07.2025 | F13: 12005327 | H13: 07.07.2025 | I13: =+MID(H13,4,2) -> 07 | J13: 50 | K13: -100000 | L13: IDR | M13: -100000 | N13: IDR | R13: R124 | S13: 498/PPC/VI/2025 | T13: SURVEY DAN ANALISA | U13: BY COO KADIN ASSUDAMAL EBP 2411775668 | V13: =+VLOOKUP(U13,'FBCJ Jul-Des 2025'!$G$10:$P$1302,8,0) -> 70009110 | W13: =+VLOOKUP(V13,Sheet1!$A$2:$B$27,2,0) -> Biaya Survey dan Analisa | X13: =+VLOOKUP(U13,'FBCJ Jul-Des 2025'!$G$10:$P$1302,9,0) -> P206D1SLSS | Y13: SP | Z13: 1495275 | AA13: 20250707 | AB13: 100000
C14: 10000001 | D14: 07.07.2025 | F14: 12005328 | H14: 07.07.2025 | I14: =+MID(H14,4,2) -> 07 | J14: 50 | K14: -100000 | L14: IDR | M14: -100000 | N14: IDR | R14: R124 | S14: 498/PPC/VI/2025 | T14: SURVEY DAN ANALISA | U14: BY COO KADIN ASSUDAMAL EBP 2411775669 | V14: =+VLOOKUP(U14,'FBCJ Jul-Des 2025'!$G$10:$P$1302,8,0) -> 70009110 | W14: =+VLOOKUP(V14,Sheet1!$A$2:$B$27,2,0) -> Biaya Survey dan Analisa | X14: =+VLOOKUP(U14,'FBCJ Jul-Des 2025'!$G$10:$P$1302,9,0) -> C206D1SLSS | Y14: SP | Z14: 1495275 | AA14: 20250707 | AB14: 100000
C15: 10000001 | D15: 07.07.2025 | F15: 12005329 | H15: 07.07.2025 | I15: =+MID(H15,4,2) -> 07 | J15: 50 | K15: -100000 | L15: IDR | M15: -100000 | N15: IDR | R15: R124 | S15: 498/PPC/VI/2025 | T15: SURVEY DAN ANALISA | U15: BY COO KADIN ASSUDAMAL EBP 2411775670 | V15: =+VLOOKUP(U15,'FBCJ Jul-Des 2025'!$G$10:$P$1302,8,0) -> 70009110 | W15: =+VLOOKUP(V15,Sheet1!$A$2:$B$27,2,0) -> Biaya Survey dan Analisa | X15: =+VLOOKUP(U15,'FBCJ Jul-Des 2025'!$G$10:$P$1302,9,0) -> P206D1SLSS | Y15: SP | Z15: 1495275 | AA15: 20250707 | AB15: 100000
C16: 10000001 | D16: 07.07.2025 | F16: 12005330 | H16: 07.07.2025 | I16: =+MID(H16,4,2) -> 07 | J16: 50 | K16: -100000 | L16: IDR | M16: -100000 | N16: IDR | R16: R124 | S16: 498/PPC/VI/2025 | T16: SURVEY DAN ANALISA | U16: BY COO KADIN ASSUDAMAL EBP 2411775671 | V16: =+VLOOKUP(U16,'FBCJ Jul-Des 2025'!$G$10:$P$1302,8,0) -> 70009110 | W16: =+VLOOKUP(V16,Sheet1!$A$2:$B$27,2,0) -> Biaya Survey dan Analisa | X16: =+VLOOKUP(U16,'FBCJ Jul-Des 2025'!$G$10:$P$1302,9,0) -> P206D1SLSS | Y16: SP | Z16: 1495275 | AA16: 20250707 | AB16: 100000
C17: 10000001 | D17: 07.07.2025 | F17: 12005331 | H17: 07.07.2025 | I17: =+MID(H17,4,2) -> 07 | J17: 50 | K17: -50000 | L17: IDR | M17: -50000 | N17: IDR | R17: R124 | S17: 498/PPC/VI/2025 | T17: SURVEY DAN ANALISA | U17: BY HC BPOM AL JAZIRA EBP 2411775754 | V17: =+VLOOKUP(U17,'FBCJ Jul-Des 2025'!$G$10:$P$1302,8,0) -> 70009110 | W17: =+VLOOKUP(V17,Sheet1!$A$2:$B$27,2,0) -> Biaya Survey dan Analisa | X17: =+VLOOKUP(U17,'FBCJ Jul-Des 2025'!$G$10:$P$1302,9,0) -> P206D1SLSS | Y17: SP | Z17: 1495275 | AA17: 20250707 | AB17: 50000
C18: 10000001 | D18: 07.07.2025 | F18: 12005332 | H18: 07.07.2025 | I18: =+MID(H18,4,2) -> 07 | J18: 50 | K18: -940000 | L18: IDR | M18: -940000 | N18: IDR | R18: R124 | S18: 504/PPC/VI/2025 | T18: PEMEL.KEND&A.BERAT MATRL | U18: BY PEMBELIAN CAIRAN PENETRANT DAN CLEANER | V18: =+VLOOKUP(U18,'FBCJ Jul-Des 2025'!$G$10:$P$1302,8,0) -> 70101202 | W18: =+VLOOKUP(V18,Sheet1!$A$2:$B$27,2,0) -> By Pemeliharaan Kend,ABerat,Mesin-Material Pihak3 | X18: =+VLOOKUP(U18,'FBCJ Jul-Des 2025'!$G$10:$P$1302,9,0) -> R124NSS | Y18: SP | Z18: 1495275 | AA18: 20250707 | AB18: 940000
... C145: 10000001 | D145: 11.07.2025 | F145: 12005459 | H145: 11.07.2025 | I145: =+MID(H145,4,2) -> 07 | J145: 50 | K145: -50000 | L145: IDR | M145: -50000 | N145: IDR | R145: R124 | S145: 558/PPC/VII/2025 | T145: SURVEY DAN ANALISA | U145: BY HC HOME CHAIN EBP 2411775613 | V145: =+VLOOKUP(U145,'FBCJ Jul-Des 2025'!$G$10:$P$1302,8,0) -> 70009110 | W145: =+VLOOKUP(V145,Sheet1!$A$2:$B$27,2,0) -> Biaya Survey dan Analisa | X145: =+VLOOKUP(U145,'FBCJ Jul-Des 2025'!$G$10:$P$1302,9,0) -> P206D1SLSS | Y145: SP | Z145: 1495275 | AA145: 20250711 | AB145: 50000
C146: 10000001 | D146: 11.07.2025 | F146: 12005460 | H146: 11.07.2025 | I146: =+MID(H146,4,2) -> 07 | J146: 40 | K146: 32056775 | L146: IDR | M146: 32056775 | N146: IDR | R146: R124 | T146: BANK IN TRANSIT | U146: PETTY CASH RUNGKUT SURABAYA PERIODE 01-11 JULI 25 | Y146: SP | Z146: 1495275 | AA146: 20250711 | AB146: 32056775
C147: 10000001 | D147: 16.07.2025 | F147: 12005952 | H147: 16.07.2025 | I147: =+MID(H147,4,2) -> 07 | J147: 50 | K147: -629000 | L147: IDR | M147: -629000 | N147: IDR | R147: R124 | T147: PBAIKN&PRAWATN PRABT MATR | U147: BY PEMB EXHAUST FAN, TIMP FLOOR MARKING | V147: =+VLOOKUP(U147,'FBCJ Jul-Des 2025'!$G$10:$P$1302,8,0) -> 70101114 | W147: =+VLOOKUP(V147,Sheet1!$A$2:$B$27,2,0) -> By Perbaikan & Perawatan Perabot Material Pihak3 | X147: =+VLOOKUP(U147,'FBCJ Jul-Des 2025'!$G$10:$P$1302,9,0) -> R124TCP | Y147: SP | Z147: 1495275 | AA147: 20250716 | AB147: 629000
C148: 10000001 | D148: 16.07.2025 | F148: 12005953 | H148: 16.07.2025 | I148: =+MID(H148,4,2) -> 07 | J148: 50 | K148: -303100 | L148: IDR | M148: -303100 | N148: IDR | R148: R124 | T148: PEMEL.KEND&A.BERAT MATRL | U148: BY PEMB WIPER SPRING U/ MOTOR POMPA F204 | V148: =+VLOOKUP(U148,'FBCJ Jul-Des 2025'!$G$10:$P$1302,8,0) -> 70101202 | W148: =+VLOOKUP(V148,Sheet1!$A$2:$B$27,2,0) -> By Pemeliharaan Kend,ABerat,Mesin-Material Pihak3 | X148: =+VLOOKUP(U148,'FBCJ Jul-Des 2025'!$G$10:$P$1302,9,0) -> R124REF3 | Y148: SP | Z148: 1495275 | AA148: 20250716 | AB148: 303100
C149: 10000001 | D149: 16.07.2025 | F149: 12005954 | H149: 16.07.2025 | I149: =+MID(H149,4,2) -> 07 | J149: 50 | K149: -290500 | L149: IDR | M149: -290500 | N149: IDR | R149: R124 | T149: BIAYA MESS | U149: BY PDAM MESS PKTJAND JULI 2025 | V149: =+VLOOKUP(U149,'FBCJ Jul-Des 2025'!$G$10:$P$1302,8,0) -> 70107100 | W149: =+VLOOKUP(V149,Sheet1!$A$2:$B$27,2,0) -> Biaya Mess | X149: =+VLOOKUP(U149,'FBCJ Jul-Des 2025'!$G$10:$P$1302,9,0) -> R124D1HRGA | Y149: SP | Z149: 1495275 | AA149: 20250716 | AB149: 290500
C150: 10000001 | D150: 16.07.2025 | F150: 12005955 | H150: 16.07.2025 | I150: =+MID(H150,4,2) -> 07 | J150: 50 | K150: -304800 | L150: IDR | M150: -304800 | N150: IDR | R150: R124 | T150: PERLENGKAPAN FOTOCOPY | U150: BY CETAK POSTER, BANNER, TAGGING PRP | V150: =+VLOOKUP(U150,'FBCJ Jul-Des 2025'!$G$10:$P$1302,8,0) -> 70108110 | W150: =+VLOOKUP(V150,Sheet1!$A$2:$B$27,2,0) -> Biaya Fotocopy | X150: =+VLOOKUP(U150,'FBCJ Jul-Des 2025'!$G$10:$P$1302,9,0) -> R124QMR | Y150: SP | Z150: 1495275 | AA150: 20250716 | AB150: 304800
C151: 10000001 | D151: 16.07.2025 | F151: 12005956 | H151: 16.07.2025 | I151: =+MID(H151,4,2) -> 07 | J151: 50 | K151: -500000 | L151: IDR | M151: -500000 | N151: IDR | R151: R124 | T151: OLAHRAGA DAN PERMAINAN | U151: BY OLAHRAGA 11/07/2025 | V151: =+VLOOKUP(U151,'FBCJ Jul-Des 2025'!$G$10:$P$1302,8,0) -> 70107300 | W151: =+VLOOKUP(V151,Sheet1!$A$2:$B$27,2,0) -> Biaya Olahraga Dan Permainan | X151: =+VLOOKUP(U151,'FBCJ Jul-Des 2025'!$G$10:$P$1302,9,0) -> R124D1HRDV | Y151: SP | Z151: 1495275 | AA151: 20250716 | AB151: 500000
C152: 10000001 | D152: 16.07.2025 | F152: 12005957 | H152: 16.07.2025 | I152: =+MID(H152,4,2) -> 07 | J152: 50 | K152: -331500 | L152: IDR | M152: -331500 | N152: IDR | R152: R124 | T152: MAKANAN DAN MINUMAN | U152: BY SNACK KUNJUNGAN SLF | V152: =+VLOOKUP(U152,'FBCJ Jul-Des 2025'!$G$10:$P$1302,8,0) -> 70107600 | W152: =+VLOOKUP(V152,Sheet1!$A$2:$B$27,2,0) -> Biaya Konsumsi Kantor | X152: =+VLOOKUP(U152,'FBCJ Jul-Des 2025'!$G$10:$P$1302,9,0) -> R124D1HRGA | Y152: SP | Z152: 1495275 | AA152: 20250716 | AB152: 331500
C153: 10000001 | D153: 16.07.2025 | F153: 12005958 | H153: 16.07.2025 | I153: =+MID(H153,4,2) -> 07 | J153: 50 | K153: -1000000 | L153: IDR | M153: -1000000 | N153: IDR | R153: R124 | T153: UMUM & ADMIN LAIN | U153: BY PEMB MATERAI | V153: =+VLOOKUP(U153,'FBCJ Jul-Des 2025'!$G$10:$P$1302,8,0) -> 70119300 | W153: =+VLOOKUP(V153,Sheet1!$A$2:$B$27,2,0) -> Biaya Umum dan Administrasi | X153: =+VLOOKUP(U153,'FBCJ Jul-Des 2025'!$G$10:$P$1302,9,0) -> R124D1PRCN | Y153: SP | Z153: 1495275 | AA153: 20250716 | AB153: 1000000
C154: 10000001 | D154: 16.07.2025 | F154: 12005959 | H154: 16.07.2025 | I154: =+MID(H154,4,2) -> 07 | J154: 50 | K154: -153000 | L154: IDR | M154: -153000 | N154: IDR | R154: R124 | T154: PEMEL.BNGAN&PSARANA MATRL | U154: BY PEMB KUAS U/ CAT | V154: =+VLOOKUP(U154,'FBCJ Jul-Des 2025'!$G$10:$P$1302,8,0) -> 70101102 | W154: =+VLOOKUP(V154,Sheet1!$A$2:$B$27,2,0) -> By Pemeliharaan BgnanPrasarana Material Pihak3 | X154: =+VLOOKUP(U154,'FBCJ Jul-Des 2025'!$G$10:$P$1302,9,0) -> R124REF | Y154: SP | Z154: 1495275 | AA154: 20250716 | AB154: 153000
C155: 10000001 | D155: 16.07.2025 | F155: 12005960 | H155: 16.07.2025 | I155: =+MID(H155,4,2) -> 07 | J155: 50 | K155: -50000 | L155: IDR | M155: -50000 | N155: IDR | R155: R124 | T155: SURVEY DAN ANALISA | U155: BY HC SG OILSEED EBP 2411776092 | V155: =+VLOOKUP(U155,'FBCJ Jul-Des 2025'!$G$10:$P$1302,8,0) -> 70009110 | W155: =+VLOOKUP(V155,Sheet1!$A$2:$B$27,2,0) -> Biaya Survey dan Analisa | X155: =+VLOOKUP(U155,'FBCJ Jul-Des 2025'!$G$10:$P$1302,9,0) -> P206D1SLSS | Y155: SP | Z155: 1495275 | AA155: 20250716 | AB155: 50000
C156: 10000001 | D156: 16.07.2025 | F156: 12005961 | H156: 16.07.2025 | I156: =+MID(H156,4,2) -> 07 | J156: 50 | K156: -50000 | L156: IDR | M156: -50000 | N156: IDR | R156: R124 | T156: SURVEY DAN ANALISA | U156: BY HC SG OILSEED EBP 2411776096 | V156: =+VLOOKUP(U156,'FBCJ Jul-Des 2025'!$G$10:$P$1302,8,0) -> 70009110 | W156: =+VLOOKUP(V156,Sheet1!$A$2:$B$27,2,0) -> Biaya Survey dan Analisa | X156: =+VLOOKUP(U156,'FBCJ Jul-Des 2025'!$G$10:$P$1302,9,0) -> P206D1SLSS | Y156: SP | Z156: 1495275 | AA156: 20250716 | AB156: 50000
C157: 10000001 | D157: 16.07.2025 | F157: 12005962 | H157: 16.07.2025 | I157: =+MID(H157,4,2) -> 07 | J157: 50 | K157: -50000 | L157: IDR | M157: -50000 | N157: IDR | R157: R124 | T157: SURVEY DAN ANALISA | U157: BY HC MONDELEZ EBP 2411776205 | V157: =+VLOOKUP(U157,'FBCJ Jul-Des 2025'!$G$10:$P$1302,8,0) -> 70009110 | W157: =+VLOOKUP(V157,Sheet1!$A$2:$B$27,2,0) -> Biaya Survey dan Analisa | X157: =+VLOOKUP(U157,'FBCJ Jul-Des 2025'!$G$10:$P$1302,9,0) -> P206D1SLSS | Y157: SP | Z157: 1495275 | AA157: 20250716 | AB157: 50000
C158: 10000001 | D158: 16.07.2025 | F158: 12005963 | H158: 16.07.2025 | I158: =+MID(H158,4,2) -> 07 | J158: 50 | K158: -50000 | L158: IDR | M158: -50000 | N158: IDR | R158: R124 | T158: SURVEY DAN ANALISA | U158: BY HC THAI GLICO EBP 2411776134 | V158: =+VLOOKUP(U158,'FBCJ Jul-Des 2025'!$G$10:$P$1302,8,0) -> 70009110 | W158: =+VLOOKUP(V158,Sheet1!$A$2:$B$27,2,0) -> Biaya Survey dan Analisa | X158: =+VLOOKUP(U158,'FBCJ Jul-Des 2025'!$G$10:$P$1302,9,0) -> P206D1SLSS | Y158: SP | Z158: 1495275 | AA158: 20250716 | AB158: 50000
... C175: 10000001 | D175: 17.07.2025 | F175: 12005980 | H175: 17.07.2025 | I175: =+MID(H175,4,2) -> 07 | J175: 50 | K175: -500000 | L175: IDR | M175: -500000 | N175: IDR | R175: R124 | T175: MAKANAN DAN MINUMAN | U175: BY KONSUMSI SC MEETING 17/07/2025 | V175: =+VLOOKUP(U175,'FBCJ Jul-Des 2025'!$G$10:$P$1302,8,0) -> 70107600 | W175: =+VLOOKUP(V175,Sheet1!$A$2:$B$27,2,0) -> Biaya Konsumsi Kantor | X175: =+VLOOKUP(U175,'FBCJ Jul-Des 2025'!$G$10:$P$1302,9,0) -> R124D1MGMT | Y175: SP | Z175: 1495275 | AA175: 20250717 | AB175: 500000
C176: 10000001 | D176: 25.07.2025 | F176: 12005981 | H176: 25.07.2025 | I176: =+MID(H176,4,2) -> 07 | J176: 50 | K176: -991000 | L176: IDR | M176: -991000 | N176: IDR | R176: R124 | S176: 571/PPC/VII/2025 | T176: PEMEL.KEND&A.BERAT MATRL | U176: BY PEMB NIPPLE SELANG PVC, ELBOW SS, DLL | V176: =+VLOOKUP(U176,'FBCJ Jul-Des 2025'!$G$10:$P$1302,8,0) -> 70101202 | W176: =+VLOOKUP(V176,Sheet1!$A$2:$B$27,2,0) -> By Pemeliharaan Kend,ABerat,Mesin-Material Pihak3 | X176: =+VLOOKUP(U176,'FBCJ Jul-Des 2025'!$G$10:$P$1302,9,0) -> R124WTT | Y176: SP | Z176: 1495275 | AA176: 20250725 | AB176: 991000
C177: 10000001 | D177: 25.07.2025 | F177: 12005982 | H177: 25.07.2025 | I177: =+MID(H177,4,2) -> 07 | J177: 50 | K177: -904127 | L177: IDR | M177: -904127 | N177: IDR | R177: R124 | S177: 577/PPC/VII/2025 | T177: PBAIKN&PRAWATN PRABT MATR | U177: BY PEMB TANGGA LIPAT TELESKOPIK | V177: =+VLOOKUP(U177,'FBCJ Jul-Des 2025'!$G$10:$P$1302,8,0) -> 70101114 | W177: =+VLOOKUP(V177,Sheet1!$A$2:$B$27,2,0) -> By Perbaikan & Perawatan Perabot Material Pihak3 | X177: =+VLOOKUP(U177,'FBCJ Jul-Des 2025'!$G$10:$P$1302,9,0) -> R124NSS | Y177: SP | Z177: 1495275 | AA177: 20250725 | AB177: 904127
C178: 10000001 | D178: 25.07.2025 | F178: 12005983 | H178: 25.07.2025 | I178: =+MID(H178,4,2) -> 07 | J178: 50 | K178: -50000 | L178: IDR | M178: -50000 | N178: IDR | R178: R124 | S178: 587/PPC/VII/2025 | T178: SURVEY DAN ANALISA | U178: BY HC AST PVT EBP 2411776266 | V178: =+VLOOKUP(U178,'FBCJ Jul-Des 2025'!$G$10:$P$1302,8,0) -> 70009110 | W178: =+VLOOKUP(V178,Sheet1!$A$2:$B$27,2,0) -> Biaya Survey dan Analisa | X178: =+VLOOKUP(U178,'FBCJ Jul-Des 2025'!$G$10:$P$1302,9,0) -> P206D1SLSS | Y178: SP | Z178: 1495275 | AA178: 20250725 | AB178: 50000
C179: 10000001 | D179: 25.07.2025 | F179: 12005984 | H179: 25.07.2025 | I179: =+MID(H179,4,2) -> 07 | J179: 50 | K179: -50000 | L179: IDR | M179: -50000 | N179: IDR | R179: R124 | S179: 587/PPC/VII/2025 | T179: SURVEY DAN ANALISA | U179: BY HC SG OILSEED EBP 2411775747 | V179: =+VLOOKUP(U179,'FBCJ Jul-Des 2025'!$G$10:$P$1302,8,0) -> 70009110 | W179: =+VLOOKUP(V179,Sheet1!$A$2:$B$27,2,0) -> Biaya Survey dan Analisa | X179: =+VLOOKUP(U179,'FBCJ Jul-Des 2025'!$G$10:$P$1302,9,0) -> P206D1SLSS | Y179: SP | Z179: 1495275 | AA179: 20250725 | AB179: 50000
C180: 10000001 | D180: 25.07.2025 | F180: 12005985 | H180: 25.07.2025 | I180: =+MID(H180,4,2) -> 07 | J180: 50 | K180: -50000 | L180: IDR | M180: -50000 | N180: IDR | R180: R124 | S180: 587/PPC/VII/2025 | T180: SURVEY DAN ANALISA | U180: BY HC SG OILSEED EBP 2411776233 | V180: =+VLOOKUP(U180,'FBCJ Jul-Des 2025'!$G$10:$P$1302,8,0) -> 70009110 | W180: =+VLOOKUP(V180,Sheet1!$A$2:$B$27,2,0) -> Biaya Survey dan Analisa | X180: =+VLOOKUP(U180,'FBCJ Jul-Des 2025'!$G$10:$P$1302,9,0) -> P206D1SLSS | Y180: SP | Z180: 1495275 | AA180: 20250725 | AB180: 50000
C181: 10000001 | D181: 25.07.2025 | F181: 12005986 | H181: 25.07.2025 | I181: =+MID(H181,4,2) -> 07 | J181: 50 | K181: -200000 | L181: IDR | M181: -200000 | N181: IDR | R181: R124 | S181: 587/PPC/VII/2025 | T181: SURVEY DAN ANALISA | U181: BY COO KADIN AST PVT EBP 2411776266 | V181: =+VLOOKUP(U181,'FBCJ Jul-Des 2025'!$G$10:$P$1302,8,0) -> 70009110 | W181: =+VLOOKUP(V181,Sheet1!$A$2:$B$27,2,0) -> Biaya Survey dan Analisa | X181: =+VLOOKUP(U181,'FBCJ Jul-Des 2025'!$G$10:$P$1302,9,0) -> P206D1SLSS | Y181: SP | Z181: 1495275 | AA181: 20250725 | AB181: 200000
C182: 10000001 | D182: 25.07.2025 | F182: 12005987 | H182: 25.07.2025 | I182: =+MID(H182,4,2) -> 07 | J182: 50 | K182: -301000 | L182: IDR | M182: -301000 | N182: IDR | R182: R124 | S182: 592/PPC/VII/2025 | T182: RISET/PENGEMBANGAN PRODUK | U182: BY SENSORY KFC, McD | V182: =+VLOOKUP(U182,'FBCJ Jul-Des 2025'!$G$10:$P$1302,8,0) -> 70115100 | W182: =+VLOOKUP(V182,Sheet1!$A$2:$B$27,2,0) -> Biaya Riset, Pengembangan, dan Laboratorium | X182: =+VLOOKUP(U182,'FBCJ Jul-Des 2025'!$G$10:$P$1302,9,0) -> R124QCA | Y182: SP | Z182: 1495275 | AA182: 20250725 | AB182: 301000
C183: 10000001 | D183: 25.07.2025 | F183: 12005988 | H183: 25.07.2025 | I183: =+MID(H183,4,2) -> 07 | J183: 50 | K183: -264000 | L183: IDR | M183: -264000 | N183: IDR | R183: R124 | S183: 592/PPC/VII/2025 | T183: PBAIKN&PRAWATN PRABT MATR | U183: BY PEMB SLING | V183: =+VLOOKUP(U183,'FBCJ Jul-Des 2025'!$G$10:$P$1302,8,0) -> 70101114 | W183: =+VLOOKUP(V183,Sheet1!$A$2:$B$27,2,0) -> By Perbaikan & Perawatan Perabot Material Pihak3 | X183: =+VLOOKUP(U183,'FBCJ Jul-Des 2025'!$G$10:$P$1302,9,0) -> R124QCA | Y183: SP | Z183: 1495275 | AA183: 20250725 | AB183: 264000
C184: 10000001 | D184: 25.07.2025 | F184: 12005989 | H184: 25.07.2025 | I184: =+MID(H184,4,2) -> 07 | J184: 50 | K184: -44000 | L184: IDR | M184: -44000 | N184: IDR | R184: R124 | S184: 592/PPC/VII/2025 | T184: UMUM & ADMIN LAIN | U184: BY ONGKIR SAMPLE KE QUALIS | V184: =+VLOOKUP(U184,'FBCJ Jul-Des 2025'!$G$10:$P$1302,8,0) -> 70119300 | W184: =+VLOOKUP(V184,Sheet1!$A$2:$B$27,2,0) -> Biaya Umum dan Administrasi | X184: =+VLOOKUP(U184,'FBCJ Jul-Des 2025'!$G$10:$P$1302,9,0) -> R124QCA | Y184: SP | Z184: 1495275 | AA184: 20250725 | AB184: 44000
C185: 10000001 | D185: 25.07.2025 | F185: 12005990 | H185: 25.07.2025 | I185: =+MID(H185,4,2) -> 07 | J185: 50 | K185: -50000 | L185: IDR | M185: -50000 | N185: IDR | R185: R124 | S185: 593/PPC/VII/2025 | T185: SURVEY DAN ANALISA | U185: BY HC SG OILSEED EBP 2411775745 | V185: =+VLOOKUP(U185,'FBCJ Jul-Des 2025'!$G$10:$P$1302,8,0) -> 70009110 | W185: =+VLOOKUP(V185,Sheet1!$A$2:$B$27,2,0) -> Biaya Survey dan Analisa | X185: =+VLOOKUP(U185,'FBCJ Jul-Des 2025'!$G$10:$P$1302,9,0) -> P206D1SLSS | Y185: SP | Z185: 1495275 | AA185: 20250725 | AB185: 50000
...

Sheet Sheet1
C1: 07 | D1: 08 | E1: 09 | F1: 10 | G1: 11 | H1: 12 | I1: Total | L1: 07 | M1: 08 | N1: 09 | O1: 10 | P1: 11 | Q1: 12 | R1: Total | AA1: Cost Center | AB1: Total | AK1: Cost Center | AL1: Total
A2: 15000900 | B2: Biaya Lainnya Yang Dibayar Di Muka | C2: =+SUMIFS('List Petty Cash Jul-Des 25'!$AB:$AB,'List Petty Cash Jul-Des 25'!$I:$I,Sheet1!C$1,'List Petty Cash Jul-Des 25'!$V:$V,Sheet1!$A2) -> 131000 | D2: =+SUMIFS('List Petty Cash Jul-Des 25'!$AB:$AB,'List Petty Cash Jul-Des 25'!$I:$I,Sheet1!D$1,'List Petty Cash Jul-Des 25'!$V:$V,Sheet1!$A2) -> 930000 | E2: =+SUMIFS('List Petty Cash Jul-Des 25'!$AB:$AB,'List Petty Cash Jul-Des 25'!$I:$I,Sheet1!E$1,'List Petty Cash Jul-Des 25'!$V:$V,Sheet1!$A2) -> 1203853 | F2: =+SUMIFS('List Petty Cash Jul-Des 25'!$AB:$AB,'List Petty Cash Jul-Des 25'!$I:$I,Sheet1!F$1,'List Petty Cash Jul-Des 25'!$V:$V,Sheet1!$A2) -> 1469656 | G2: =+SUMIFS('List Petty Cash Jul-Des 25'!$AB:$AB,'List Petty Cash Jul-Des 25'!$I:$I,Sheet1!G$1,'List Petty Cash Jul-Des 25'!$V:$V,Sheet1!$A2) -> 4791052 | H2: =+SUMIFS('List Petty Cash Jul-Des 25'!$AB:$AB,'List Petty Cash Jul-Des 25'!$I:$I,Sheet1!H$1,'List Petty Cash Jul-Des 25'!$V:$V,Sheet1!$A2) -> 3214369 | I2: =+SUM(C2:H2) -> 11739930 | K2: - | L2: =+SUMIFS('List Petty Cash Jul-Des 25'!$AB:$AB,'List Petty Cash Jul-Des 25'!$I:$I,Sheet1!L$1,'List Petty Cash Jul-Des 25'!$X:$X,Sheet1!$K2) -> 131000 | M2: =+SUMIFS('List Petty Cash Jul-Des 25'!$AB:$AB,'List Petty Cash Jul-Des 25'!$I:$I,Sheet1!M$1,'List Petty Cash Jul-Des 25'!$X:$X,Sheet1!$K2) -> 930000 | N2: =+SUMIFS('List Petty Cash Jul-Des 25'!$AB:$AB,'List Petty Cash Jul-Des 25'!$I:$I,Sheet1!N$1,'List Petty Cash Jul-Des 25'!$X:$X,Sheet1!$K2) -> 1203853 | O2: =+SUMIFS('List Petty Cash Jul-Des 25'!$AB:$AB,'List Petty Cash Jul-Des 25'!$I:$I,Sheet1!O$1,'List Petty Cash Jul-Des 25'!$X:$X,Sheet1!$K2) -> 1469656 | P2: =+SUMIFS('List Petty Cash Jul-Des 25'!$AB:$AB,'List Petty Cash Jul-Des 25'!$I:$I,Sheet1!P$1,'List Petty Cash Jul-Des 25'!$X:$X,Sheet1!$K2) -> 4791052 | Q2: =+SUMIFS('List Petty Cash Jul-Des 25'!$AB:$AB,'List Petty Cash Jul-Des 25'!$I:$I,Sheet1!Q$1,'List Petty Cash Jul-Des 25'!$X:$X,Sheet1!$K2) -> 3214369 | R2: =+SUM(L2:Q2) -> 11739930 | S2: =+R2/$R$38*100% -> 0.036720098 | T2: 15000900 | AA2: R124D1HRGA | AB2: 107619783 | AE2: R124D1HRGA | AK2: R124D1HRGA | AL2: 107619783
A3: 70001110 | B3: Biaya Ekspor lainnya | C3: =+SUMIFS('List Petty Cash Jul-Des 25'!$AB:$AB,'List Petty Cash Jul-Des 25'!$I:$I,Sheet1!C$1,'List Petty Cash Jul-Des 25'!$V:$V,Sheet1!$A3) -> 29000 | D3: =+SUMIFS('List Petty Cash Jul-Des 25'!$AB:$AB,'List Petty Cash Jul-Des 25'!$I:$I,Sheet1!D$1,'List Petty Cash Jul-Des 25'!$V:$V,Sheet1!$A3) -> 886100 | E3: =+SUMIFS('List Petty Cash Jul-Des 25'!$AB:$AB,'List Petty Cash Jul-Des 25'!$I:$I,Sheet1!E$1,'List Petty Cash Jul-Des 25'!$V:$V,Sheet1!$A3) -> 13000 | F3: =+SUMIFS('List Petty Cash Jul-Des 25'!$AB:$AB,'List Petty Cash Jul-Des 25'!$I:$I,Sheet1!F$1,'List Petty Cash Jul-Des 25'!$V:$V,Sheet1!$A3) -> 24000 | G3: =+SUMIFS('List Petty Cash Jul-Des 25'!$AB:$AB,'List Petty Cash Jul-Des 25'!$I:$I,Sheet1!G$1,'List Petty Cash Jul-Des 25'!$V:$V,Sheet1!$A3) -> 7190000 | H3: =+SUMIFS('List Petty Cash Jul-Des 25'!$AB:$AB,'List Petty Cash Jul-Des 25'!$I:$I,Sheet1!H$1,'List Petty Cash Jul-Des 25'!$V:$V,Sheet1!$A3) -> 6918000 | I3: =+SUM(C3:H3) -> 15060100 | K3: C206D1SLSS | L3: =+SUMIFS('List Petty Cash Jul-Des 25'!$AB:$AB,'List Petty Cash Jul-Des 25'!$I:$I,Sheet1!L$1,'List Petty Cash Jul-Des 25'!$X:$X,Sheet1!$K3) -> 820000 | M3: =+SUMIFS('List Petty Cash Jul-Des 25'!$AB:$AB,'List Petty Cash Jul-Des 25'!$I:$I,Sheet1!M$1,'List Petty Cash Jul-Des 25'!$X:$X,Sheet1!$K3) -> 1870000 | N3: =+SUMIFS('List Petty Cash Jul-Des 25'!$AB:$AB,'List Petty Cash Jul-Des 25'!$I:$I,Sheet1!N$1,'List Petty Cash Jul-Des 25'!$X:$X,Sheet1!$K3) -> 1280000 | O3: =+SUMIFS('List Petty Cash Jul-Des 25'!$AB:$AB,'List Petty Cash Jul-Des 25'!$I:$I,Sheet1!O$1,'List Petty Cash Jul-Des 25'!$X:$X,Sheet1!$K3) -> 2775000 | P3: =+SUMIFS('List Petty Cash Jul-Des 25'!$AB:$AB,'List Petty Cash Jul-Des 25'!$I:$I,Sheet1!P$1,'List Petty Cash Jul-Des 25'!$X:$X,Sheet1!$K3) -> 1778000 | Q3: =+SUMIFS('List Petty Cash Jul-Des 25'!$AB:$AB,'List Petty Cash Jul-Des 25'!$I:$I,Sheet1!Q$1,'List Petty Cash Jul-Des 25'!$X:$X,Sheet1!$K3) -> 1630000 | R3: =+SUM(L3:Q3) -> 10153000 | S3: =+R3/$R$38*100% -> 0.031756506 | T3: 70001110 | AA3: P206D1SLSS | AB3: 33069100 | AE3: 70106400 | AF3: Biaya Bahan Bakar | AG3: 44610000 | AK3: P206D1SLSS | AL3: 33069100
A4: 70009110 | B4: Biaya Survey dan Analisa | C4: =+SUMIFS('List Petty Cash Jul-Des 25'!$AB:$AB,'List Petty Cash Jul-Des 25'!$I:$I,Sheet1!C$1,'List Petty Cash Jul-Des 25'!$V:$V,Sheet1!$A4) -> 7000000 | D4: =+SUMIFS('List Petty Cash Jul-Des 25'!$AB:$AB,'List Petty Cash Jul-Des 25'!$I:$I,Sheet1!D$1,'List Petty Cash Jul-Des 25'!$V:$V,Sheet1!$A4) -> 5600000 | E4: =+SUMIFS('List Petty Cash Jul-Des 25'!$AB:$AB,'List Petty Cash Jul-Des 25'!$I:$I,Sheet1!E$1,'List Petty Cash Jul-Des 25'!$V:$V,Sheet1!$A4) -> 5200000 | F4: =+SUMIFS('List Petty Cash Jul-Des 25'!$AB:$AB,'List Petty Cash Jul-Des 25'!$I:$I,Sheet1!F$1,'List Petty Cash Jul-Des 25'!$V:$V,Sheet1!$A4) -> 9350000 | G4: =+SUMIFS('List Petty Cash Jul-Des 25'!$AB:$AB,'List Petty Cash Jul-Des 25'!$I:$I,Sheet1!G$1,'List Petty Cash Jul-Des 25'!$V:$V,Sheet1!$A4) -> 0 | H4: =+SUMIFS('List Petty Cash Jul-Des 25'!$AB:$AB,'List Petty Cash Jul-Des 25'!$I:$I,Sheet1!H$1,'List Petty Cash Jul-Des 25'!$V:$V,Sheet1!$A4) -> 0 | I4: =+SUM(C4:H4) -> 27150000 | K4: H200D1MMDP | L4: =+SUMIFS('List Petty Cash Jul-Des 25'!$AB:$AB,'List Petty Cash Jul-Des 25'!$I:$I,Sheet1!L$1,'List Petty Cash Jul-Des 25'!$X:$X,Sheet1!$K4) -> 0 | M4: =+SUMIFS('List Petty Cash Jul-Des 25'!$AB:$AB,'List Petty Cash Jul-Des 25'!$I:$I,Sheet1!M$1,'List Petty Cash Jul-Des 25'!$X:$X,Sheet1!$K4) -> 0 | N4: =+SUMIFS('List Petty Cash Jul-Des 25'!$AB:$AB,'List Petty Cash Jul-Des 25'!$I:$I,Sheet1!N$1,'List Petty Cash Jul-Des 25'!$X:$X,Sheet1!$K4) -> 0 | O4: =+SUMIFS('List Petty Cash Jul-Des 25'!$AB:$AB,'List Petty Cash Jul-Des 25'!$I:$I,Sheet1!O$1,'List Petty Cash Jul-Des 25'!$X:$X,Sheet1!$K4) -> 135000 | P4: =+SUMIFS('List Petty Cash Jul-Des 25'!$AB:$AB,'List Petty Cash Jul-Des 25'!$I:$I,Sheet1!P$1,'List Petty Cash Jul-Des 25'!$X:$X,Sheet1!$K4) -> 7478800 | Q4: =+SUMIFS('List Petty Cash Jul-Des 25'!$AB:$AB,'List Petty Cash Jul-Des 25'!$I:$I,Sheet1!Q$1,'List Petty Cash Jul-Des 25'!$X:$X,Sheet1!$K4) -> 1335000 | R4: =+SUM(L4:Q4) -> 8948800 | S4: =+R4/$R$38*100% -> 0.027990015 | T4: 70009110 | AA4: R124D1HRDV | AB4: 22378764 | AE4: 70106100 | AF4: Biaya Transportasi Lokal | AG4: 26336300 | AK4: R124D1HRDV | AL4: 22378764
A5: 70101102 | B5: By Pemeliharaan BgnanPrasarana Material Pihak3 | C5: =+SUMIFS('List Petty Cash Jul-Des 25'!$AB:$AB,'List Petty Cash Jul-Des 25'!$I:$I,Sheet1!C$1,'List Petty Cash Jul-Des 25'!$V:$V,Sheet1!$A5) -> 2744420 | D5: =+SUMIFS('List Petty Cash Jul-Des 25'!$AB:$AB,'List Petty Cash Jul-Des 25'!$I:$I,Sheet1!D$1,'List Petty Cash Jul-Des 25'!$V:$V,Sheet1!$A5) -> 1138300 | E5: =+SUMIFS('List Petty Cash Jul-Des 25'!$AB:$AB,'List Petty Cash Jul-Des 25'!$I:$I,Sheet1!E$1,'List Petty Cash Jul-Des 25'!$V:$V,Sheet1!$A5) -> 0 | F5: =+SUMIFS('List Petty Cash Jul-Des 25'!$AB:$AB,'List Petty Cash Jul-Des 25'!$I:$I,Sheet1!F$1,'List Petty Cash Jul-Des 25'!$V:$V,Sheet1!$A5) -> 2443000 | G5: =+SUMIFS('List Petty Cash Jul-Des 25'!$AB:$AB,'List Petty Cash Jul-Des 25'!$I:$I,Sheet1!G$1,'List Petty Cash Jul-Des 25'!$V:$V,Sheet1!$A5) -> 1956310 | H5: =+SUMIFS('List Petty Cash Jul-Des 25'!$AB:$AB,'List Petty Cash Jul-Des 25'!$I:$I,Sheet1!H$1,'List Petty Cash Jul-Des 25'!$V:$V,Sheet1!$A5) -> 1890250 | I5: =+SUM(C5:H5) -> 10172280 | K5: M204D1COMM | L5: =+SUMIFS('List Petty Cash Jul-Des 25'!$AB:$AB,'List Petty Cash Jul-Des 25'!$I:$I,Sheet1!L$1,'List Petty Cash Jul-Des 25'!$X:$X,Sheet1!$K5) -> 3702000 | M5: =+SUMIFS('List Petty Cash Jul-Des 25'!$AB:$AB,'List Petty Cash Jul-Des 25'!$I:$I,Sheet1!M$1,'List Petty Cash Jul-Des 25'!$X:$X,Sheet1!$K5) -> 4927000 | N5: =+SUMIFS('List Petty Cash Jul-Des 25'!$AB:$AB,'List Petty Cash Jul-Des 25'!$I:$I,Sheet1!N$1,'List Petty Cash Jul-Des 25'!$X:$X,Sheet1!$K5) -> 763000 | O5: =+SUMIFS('List Petty Cash Jul-Des 25'!$AB:$AB,'List Petty Cash Jul-Des 25'!$I:$I,Sheet1!O$1,'List Petty Cash Jul-Des 25'!$X:$X,Sheet1!$K5) -> 3540000 | P5: =+SUMIFS('List Petty Cash Jul-Des 25'!$AB:$AB,'List Petty Cash Jul-Des 25'!$I:$I,Sheet1!P$1,'List Petty Cash Jul-Des 25'!$X:$X,Sheet1!$K5) -> 1120000 | Q5: =+SUMIFS('List Petty Cash Jul-Des 25'!$AB:$AB,'List Petty Cash Jul-Des 25'!$I:$I,Sheet1!Q$1,'List Petty Cash Jul-Des 25'!$X:$X,Sheet1!$K5) -> 1730300 | R5: =+SUM(L5:Q5) -> 15782300 | S5: =+R5/$R$38*100% -> 0.049363804 | T5: 70101102 | AA5: R124QCA | AB5: 19964591 | AE5: 70101114 | AF5: By Perbaikan & Perawatan Perabot Material Pihak3 | AG5: 12884723 | AK5: R124QCA | AL5: 19964591
A6: 70101114 | B6: By Perbaikan & Perawatan Perabot Material Pihak3 | C6: =+SUMIFS('List Petty Cash Jul-Des 25'!$AB:$AB,'List Petty Cash Jul-Des 25'!$I:$I,Sheet1!C$1,'List Petty Cash Jul-Des 25'!$V:$V,Sheet1!$A6) -> 8742306 | D6: =+SUMIFS('List Petty Cash Jul-Des 25'!$AB:$AB,'List Petty Cash Jul-Des 25'!$I:$I,Sheet1!D$1,'List Petty Cash Jul-Des 25'!$V:$V,Sheet1!$A6) -> 4004078 | E6: =+SUMIFS('List Petty Cash Jul-Des 25'!$AB:$AB,'List Petty Cash Jul-Des 25'!$I:$I,Sheet1!E$1,'List Petty Cash Jul-Des 25'!$V:$V,Sheet1!$A6) -> 5781593 | F6: =+SUMIFS('List Petty Cash Jul-Des 25'!$AB:$AB,'List Petty Cash Jul-Des 25'!$I:$I,Sheet1!F$1,'List Petty Cash Jul-Des 25'!$V:$V,Sheet1!$A6) -> 7588405 | G6: =+SUMIFS('List Petty Cash Jul-Des 25'!$AB:$AB,'List Petty Cash Jul-Des 25'!$I:$I,Sheet1!G$1,'List Petty Cash Jul-Des 25'!$V:$V,Sheet1!$A6) -> 2812320 | H6: =+SUMIFS('List Petty Cash Jul-Des 25'!$AB:$AB,'List Petty Cash Jul-Des 25'!$I:$I,Sheet1!H$1,'List Petty Cash Jul-Des 25'!$V:$V,Sheet1!$A6) -> 12627978 | I6: =+SUM(C6:H6) -> 41556680 | K6: P206D1SLSC | L6: =+SUMIFS('List Petty Cash Jul-Des 25'!$AB:$AB,'List Petty Cash Jul-Des 25'!$I:$I,Sheet1!L$1,'List Petty Cash Jul-Des 25'!$X:$X,Sheet1!$K6) -> 350000 | M6: =+SUMIFS('List Petty Cash Jul-Des 25'!$AB:$AB,'List Petty Cash Jul-Des 25'!$I:$I,Sheet1!M$1,'List Petty Cash Jul-Des 25'!$X:$X,Sheet1!$K6) -> 350000 | N6: =+SUMIFS('List Petty Cash Jul-Des 25'!$AB:$AB,'List Petty Cash Jul-Des 25'!$I:$I,Sheet1!N$1,'List Petty Cash Jul-Des 25'!$X:$X,Sheet1!$K6) -> 700000 | O6: =+SUMIFS('List Petty Cash Jul-Des 25'!$AB:$AB,'List Petty Cash Jul-Des 25'!$I:$I,Sheet1!O$1,'List Petty Cash Jul-Des 25'!$X:$X,Sheet1!$K6) -> 400000 | P6: =+SUMIFS('List Petty Cash Jul-Des 25'!$AB:$AB,'List Petty Cash Jul-Des 25'!$I:$I,Sheet1!P$1,'List Petty Cash Jul-Des 25'!$X:$X,Sheet1!$K6) -> 400000 | Q6: =+SUMIFS('List Petty Cash Jul-Des 25'!$AB:$AB,'List Petty Cash Jul-Des 25'!$I:$I,Sheet1!Q$1,'List Petty Cash Jul-Des 25'!$X:$X,Sheet1!$K6) -> 500000 | R6: =+SUM(L6:Q6) -> 2700000 | S6: =+R6/$R$38*100% -> 0.0084450474 | T6: 70101114 | AA6: M204D1COMM | AB6: 15782300 | AE6: 70107100 | AF6: Biaya Mess | AG6: 6993000 | AK6: M204D1COMM | AL6: 15782300
A7: 70101202 | B7: By Pemeliharaan Kend,ABerat,Mesin-Material Pihak3 | C7: =+SUMIFS('List Petty Cash Jul-Des 25'!$AB:$AB,'List Petty Cash Jul-Des 25'!$I:$I,Sheet1!C$1,'List Petty Cash Jul-Des 25'!$V:$V,Sheet1!$A7) -> 6020808 | D7: =+SUMIFS('List Petty Cash Jul-Des 25'!$AB:$AB,'List Petty Cash Jul-Des 25'!$I:$I,Sheet1!D$1,'List Petty Cash Jul-Des 25'!$V:$V,Sheet1!$A7) -> 2452500 | E7: =+SUMIFS('List Petty Cash Jul-Des 25'!$AB:$AB,'List Petty Cash Jul-Des 25'!$I:$I,Sheet1!E$1,'List Petty Cash Jul-Des 25'!$V:$V,Sheet1!$A7) -> 4139620 | F7: =+SUMIFS('List Petty Cash Jul-Des 25'!$AB:$AB,'List Petty Cash Jul-Des 25'!$I:$I,Sheet1!F$1,'List Petty Cash Jul-Des 25'!$V:$V,Sheet1!$A7) -> 12044280 | G7: =+SUMIFS('List Petty Cash Jul-Des 25'!$AB:$AB,'List Petty Cash Jul-Des 25'!$I:$I,Sheet1!G$1,'List Petty Cash Jul-Des 25'!$V:$V,Sheet1!$A7) -> 2950976 | H7: =+SUMIFS('List Petty Cash Jul-Des 25'!$AB:$AB,'List Petty Cash Jul-Des 25'!$I:$I,Sheet1!H$1,'List Petty Cash Jul-Des 25'!$V:$V,Sheet1!$A7) -> 7628680 | I7: =+SUM(C7:H7) -> 35236864 | K7: P206D1SLSS | L7: =+SUMIFS('List Petty Cash Jul-Des 25'!$AB:$AB,'List Petty Cash Jul-Des 25'!$I:$I,Sheet1!L$1,'List Petty Cash Jul-Des 25'!$X:$X,Sheet1!$K7) -> 6844000 | M7: =+SUMIFS('List Petty Cash Jul-Des 25'!$AB:$AB,'List Petty Cash Jul-Des 25'!$I:$I,Sheet1!M$1,'List Petty Cash Jul-Des 25'!$X:$X,Sheet1!$K7) -> 4844100 | N7: =+SUMIFS('List Petty Cash Jul-Des 25'!$AB:$AB,'List Petty Cash Jul-Des 25'!$I:$I,Sheet1!N$1,'List Petty Cash Jul-Des 25'!$X:$X,Sheet1!$K7) -> 3643000 | O7: =+SUMIFS('List Petty Cash Jul-Des 25'!$AB:$AB,'List Petty Cash Jul-Des 25'!$I:$I,Sheet1!O$1,'List Petty Cash Jul-Des 25'!$X:$X,Sheet1!$K7) -> 5837000 | P7: =+SUMIFS('List Petty Cash Jul-Des 25'!$AB:$AB,'List Petty Cash Jul-Des 25'!$I:$I,Sheet1!P$1,'List Petty Cash Jul-Des 25'!$X:$X,Sheet1!$K7) -> 6200000 | Q7: =+SUMIFS('List Petty Cash Jul-Des 25'!$AB:$AB,'List Petty Cash Jul-Des 25'!$I:$I,Sheet1!Q$1,'List Petty Cash Jul-Des 25'!$X:$X,Sheet1!$K7) -> 5701000 | R7: =+SUM(L7:Q7) -> 33069100 | S7: =+R7/$R$38*100% -> 0.10343338 | T7: 70101202 | AA7: - | AB7: 11739930 | AE7: 70101102 | AF7: By Pemeliharaan BgnanPrasarana Material Pihak3 | AG7: 6693470
A8: 70101230 | B8: Pemakaian Sparepart Kend & A.Berat | C8: =+SUMIFS('List Petty Cash Jul-Des 25'!$AB:$AB,'List Petty Cash Jul-Des 25'!$I:$I,Sheet1!C$1,'List Petty Cash Jul-Des 25'!$V:$V,Sheet1!$A8) -> 1800000 | D8: =+SUMIFS('List Petty Cash Jul-Des 25'!$AB:$AB,'List Petty Cash Jul-Des 25'!$I:$I,Sheet1!D$1,'List Petty Cash Jul-Des 25'!$V:$V,Sheet1!$A8) -> 0 | E8: =+SUMIFS('List Petty Cash Jul-Des 25'!$AB:$AB,'List Petty Cash Jul-Des 25'!$I:$I,Sheet1!E$1,'List Petty Cash Jul-Des 25'!$V:$V,Sheet1!$A8) -> 0 | F8: =+SUMIFS('List Petty Cash Jul-Des 25'!$AB:$AB,'List Petty Cash Jul-Des 25'!$I:$I,Sheet1!F$1,'List Petty Cash Jul-Des 25'!$V:$V,Sheet1!$A8) -> 0 | G8: =+SUMIFS('List Petty Cash Jul-Des 25'!$AB:$AB,'List Petty Cash Jul-Des 25'!$I:$I,Sheet1!G$1,'List Petty Cash Jul-Des 25'!$V:$V,Sheet1!$A8) -> 0 | H8: =+SUMIFS('List Petty Cash Jul-Des 25'!$AB:$AB,'List Petty Cash Jul-Des 25'!$I:$I,Sheet1!H$1,'List Petty Cash Jul-Des 25'!$V:$V,Sheet1!$A8) -> 0 | I8: =+SUM(C8:H8) -> 1800000 | K8: R124BLR | L8: =+SUMIFS('List Petty Cash Jul-Des 25'!$AB:$AB,'List Petty Cash Jul-Des 25'!$I:$I,Sheet1!L$1,'List Petty Cash Jul-Des 25'!$X:$X,Sheet1!$K8) -> 0 | M8: =+SUMIFS('List Petty Cash Jul-Des 25'!$AB:$AB,'List Petty Cash Jul-Des 25'!$I:$I,Sheet1!M$1,'List Petty Cash Jul-Des 25'!$X:$X,Sheet1!$K8) -> 0 | N8: =+SUMIFS('List Petty Cash Jul-Des 25'!$AB:$AB,'List Petty Cash Jul-Des 25'!$I:$I,Sheet1!N$1,'List Petty Cash Jul-Des 25'!$X:$X,Sheet1!$K8) -> 0 | O8: =+SUMIFS('List Petty Cash Jul-Des 25'!$AB:$AB,'List Petty Cash Jul-Des 25'!$I:$I,Sheet1!O$1,'List Petty Cash Jul-Des 25'!$X:$X,Sheet1!$K8) -> 2325000 | P8: =+SUMIFS('List Petty Cash Jul-Des 25'!$AB:$AB,'List Petty Cash Jul-Des 25'!$I:$I,Sheet1!P$1,'List Petty Cash Jul-Des 25'!$X:$X,Sheet1!$K8) -> 2821000 | Q8: =+SUMIFS('List Petty Cash Jul-Des 25'!$AB:$AB,'List Petty Cash Jul-Des 25'!$I:$I,Sheet1!Q$1,'List Petty Cash Jul-Des 25'!$X:$X,Sheet1!$K8) -> 0 | R8: =+SUM(L8:Q8) -> 5146000 | S8: =+R8/$R$38*100% -> 0.016095635 | T8: 70101230 | AA8: C206D1SLSS | AB8: 10153000 | AE8: 70108100 | AF8: Biaya Peralatan Dan Perabot Kantor | AG8: 4247200
A9: 70102300 | B9: Biaya Poliklinik | C9: =+SUMIFS('List Petty Cash Jul-Des 25'!$AB:$AB,'List Petty Cash Jul-Des 25'!$I:$I,Sheet1!C$1,'List Petty Cash Jul-Des 25'!$V:$V,Sheet1!$A9) -> 1116900 | D9: =+SUMIFS('List Petty Cash Jul-Des 25'!$AB:$AB,'List Petty Cash Jul-Des 25'!$I:$I,Sheet1!D$1,'List Petty Cash Jul-Des 25'!$V:$V,Sheet1!$A9) -> 0 | E9: =+SUMIFS('List Petty Cash Jul-Des 25'!$AB:$AB,'List Petty Cash Jul-Des 25'!$I:$I,Sheet1!E$1,'List Petty Cash Jul-Des 25'!$V:$V,Sheet1!$A9) -> 0 | F9: =+SUMIFS('List Petty Cash Jul-Des 25'!$AB:$AB,'List Petty Cash Jul-Des 25'!$I:$I,Sheet1!F$1,'List Petty Cash Jul-Des 25'!$V:$V,Sheet1!$A9) -> 0 | G9: =+SUMIFS('List Petty Cash Jul-Des 25'!$AB:$AB,'List Petty Cash Jul-Des 25'!$I:$I,Sheet1!G$1,'List Petty Cash Jul-Des 25'!$V:$V,Sheet1!$A9) -> 0 | H9: =+SUMIFS('List Petty Cash Jul-Des 25'!$AB:$AB,'List Petty Cash Jul-Des 25'!$I:$I,Sheet1!H$1,'List Petty Cash Jul-Des 25'!$V:$V,Sheet1!$A9) -> 0 | I9: =+SUM(C9:H9) -> 1116900 | K9: R124D1EHFS | L9: =+SUMIFS('List Petty Cash Jul-Des 25'!$AB:$AB,'List Petty Cash Jul-Des 25'!$I:$I,Sheet1!L$1,'List Petty Cash Jul-Des 25'!$X:$X,Sheet1!$K9) -> 1273180 | M9: =+SUMIFS('List Petty Cash Jul-Des 25'!$AB:$AB,'List Petty Cash Jul-Des 25'!$I:$I,Sheet1!M$1,'List Petty Cash Jul-Des 25'!$X:$X,Sheet1!$K9) -> 1113500 | N9: =+SUMIFS('List Petty Cash Jul-Des 25'!$AB:$AB,'List Petty Cash Jul-Des 25'!$I:$I,Sheet1!N$1,'List Petty Cash Jul-Des 25'!$X:$X,Sheet1!$K9) -> 100000 | O9: =+SUMIFS('List Petty Cash Jul-Des 25'!$AB:$AB,'List Petty Cash Jul-Des 25'!$I:$I,Sheet1!O$1,'List Petty Cash Jul-Des 25'!$X:$X,Sheet1!$K9) -> 999700 | P9: =+SUMIFS('List Petty Cash Jul-Des 25'!$AB:$AB,'List Petty Cash Jul-Des 25'!$I:$I,Sheet1!P$1,'List Petty Cash Jul-Des 25'!$X:$X,Sheet1!$K9) -> 876800 | Q9: =+SUMIFS('List Petty Cash Jul-Des 25'!$AB:$AB,'List Petty Cash Jul-Des 25'!$I:$I,Sheet1!Q$1,'List Petty Cash Jul-Des 25'!$X:$X,Sheet1!$K9) -> 996262 | R9: =+SUM(L9:Q9) -> 5359442 | S9: =+R9/$R$38*100% -> 0.016763238 | T9: 70102300 | AA9: H200D1MMDP | AB9: 8948800 | AE9: 70107600 | AF9: Biaya Konsumsi Kantor | AG9: 4172490
